<?xml version="1.0"?>
<robot name="Ikea_chair_side_file" xmlns:xacro="http://ros.org/wiki/xacro">

<xacro:macro name="side_part" params="link_name reflect color">
	<link name="${link_name}">
	  <visual>
		<origin xyz="0 0 0" rpy="${reflect * -pi/2} 0 ${pi/2}" />
		<geometry>
		    <mesh filename="package://furniture_description/meshes/legs.STL"/>
		</geometry>
		<material name="${color}"/>
	  </visual>

		<collision>
		<origin xyz="0 0 0" rpy="${pi/2} 0 ${pi/2}" />
			<geometry>
		    	<mesh filename="package://furniture_description/meshes/legs.STL"/>
			</geometry>
		</collision>

		<inertial>
			<mass value="1" />
			<origin xyz="0 0 0" rpy="0 0 0"/>
			<inertia ixx="1e-6" ixy="0" ixz="0" iyy="1e-6" iyz="0" izz="1e-6" />
		</inertial>
	</link>

	<joint name="${link_name}_joint" type="floating">
		<parent link="world" />
		<child link = "${link_name}" />
	</joint>

	<link name="${link_name}_hole_1_1"/>
	<link name="${link_name}_hole_1_2"/>

	<joint name="${link_name}_hole_1_1_joint" type="fixed">
		<parent link="${link_name}" />
		<child link = "${link_name}_hole_1_1" />
		<origin xyz="${reflect * -0.13} 0.012 0.015" rpy="0 0 0" />  
	</joint>

	<joint name="${link_name}_hole_1_2_joint" type="fixed">
		<parent link="${link_name}" />
		<child link = "${link_name}_hole_1_2" />
		<origin xyz="${reflect * -0.13} -0.012 0.015" rpy="0 0 0" />  
	</joint>
	
	<link name="${link_name}_hole_2_1"/>
	<link name="${link_name}_hole_2_2"/>

	<joint name="${link_name}_hole_2_1_joint" type="fixed">
		<parent link="${link_name}" />
		<child link = "${link_name}_hole_2_1" />
		<origin xyz="${reflect * 0.13} 0.012 0.015" rpy="0 0 0" />  
	</joint>

	<joint name="${link_name}_hole_2_2_joint" type="fixed">
		<parent link="${link_name}" />
		<child link = "${link_name}_hole_2_2" />
		<origin xyz="${reflect * 0.13} -0.012 0.015" rpy="0 0 0" />  
	</joint>

	<link name="${link_name}_hole_3_1"/>
	<link name="${link_name}_hole_3_2"/>

	<joint name="${link_name}_hole_3_1_joint" type="fixed">
		<parent link="${link_name}" />
		<child link = "${link_name}_hole_3_1" />
		<origin xyz="${reflect *0.13} 0.193 0.015" rpy="0 0 0" />  
	</joint>

	<joint name="${link_name}_hole_3_2_joint" type="fixed">
		<parent link="${link_name}" />
		<child link = "${link_name}_hole_3_2" />
		<origin xyz="${reflect *0.13} 0.161 0.015" rpy="0 0 0" />  
	</joint>

	
	<gazebo reference="${link_name}">
		<material>Gazebo/${color}</material>
		<mu1>0.2</mu1>
		<mu2>0.2</mu2>
	</gazebo>
</xacro:macro>

</robot>
