<?xml version="1.0"?>
<robot name="ikea_chair_cushion" xmlns:xacro="http://www.ros.org/wiki/xacro">

<xacro:macro name="cushion" params="link_name color">
	<link name="${link_name}">
	  <visual>
		<origin xyz="0 0 0" rpy="${pi/2} 0 0" />
		<geometry>
		    <mesh filename="package://furniture_description/meshes/cushion.STL"/>
		</geometry>
		<material name="${color}"/>
	  </visual>
	  <collision>
		<origin xyz="0 0 0" rpy="${pi/2} 0 0" />
		<geometry>
		    <mesh filename="package://furniture_description/meshes/cushion.STL"/>
		</geometry>
	  </collision>
	</link>

	<joint name="cushion_joint" type="floating">
		<parent link="world" />
		<child link = "${link_name}" />
	</joint>

	<link name="${link_name}_hole_1_1"/>
	<link name="${link_name}_hole_1_2"/>

	<joint name="${link_name}_hole_1_1_joint" type="fixed">
		<parent link="${link_name}" />
		<child link = "${link_name}_hole_1_1" />
		<origin xyz="-0.048 -0.11 -0.007" rpy="0 ${pi} 0" />  
	</joint>

	<joint name="${link_name}_hole_1_2_joint" type="fixed">
		<parent link="${link_name}" />
		<child link = "${link_name}_hole_1_2" />
		<origin xyz="0.048 -0.11 -0.007" rpy="0 ${pi} 0" />  
	</joint>

	<link name="${link_name}_hole_2_1"/>
	<link name="${link_name}_hole_2_2"/>

	<joint name="${link_name}_hole_2_1_joint" type="fixed">
		<parent link="${link_name}" />
		<child link = "${link_name}_hole_2_1" />
		<origin xyz="-0.048 0.146 -0.007" rpy="0 ${pi} 0" />  
	</joint>

	<joint name="${link_name}_hole_2_2_joint" type="fixed">
		<parent link="${link_name}" />
		<child link = "${link_name}_hole_2_2" />
		<origin xyz="0.048 0.146 -0.007" rpy="0 ${pi} 0" />  
	</joint>

</xacro:macro>

</robot>
